Workbook

Sheet Mars
A1: Liste de client : | D1: Liste d'associé : | F1: Liste de fournisseur
A2: 4111 | B2: Jack | D2: 4551 | E2: Antoine | F2: 4016 | G2: Serveur
A3: 4112 | B3: Skye | D3: 4552 | E3: Coraline
A4: 4113 | B4: JB | D4: 4553 | E4: Roméo
A5: 4114 | B5: JusteMoi | D5: 4554 | E5: Pastry
A6: 4115 | B6: Fulzer | D6: 4555 | E6: Vorloks
A7: 4116 | B7: Itoka | D7: 4556 | E7: Loper
A8: 4117 | B8: Konei
A9: 4118 | B9: Florian
A10: 4119 | B10: Pourtoutix
A11: 41110 | B11: Scale | Q11: Coraline | U11: Antoine
A12: 41111 | B12: Kellogs | Q12: 512 | U12: 512
C13: Journal de Corqline | J13: Journal de Saatori | P13: D | R13: C | T13: D | V13: C
C14: Mois de MARS | J14: Mois de MARS | P14: =E20 -> 8.22 | R14: =F41 -> 67.27 | T14: =L20 -> 10.16 | V14: =M40 -> 2.5
C15: 45740 | J15: 45740 | P15: =E28 -> 26.8 | R15: =F57 -> 3.11 | T15: =L32 -> 5 | V15: =M58 -> 10
A16: 41111 | C16: Client - Kellogs | E16: 10 | H16: 4111 | J16: Client - Kellogs | L16: 11 | P16: =E36 -> 107.74 | R16: =F69 -> 16.85 | T16: =L35 -> 67.27
B17: 706 | C17: Prestation de service | F17: 10 | I17: 706 | J17: Prestation de service | M17: 11 | P17: =E52 -> 6.22 | R17: 20 | T17: =L43 -> 3.11
B18: 5 assets Kris Thaesler Paypal | I18: 5 assets Kris Thaesler Paypal | P18: =E60 -> 2.5 | T18: =L47 -> 16.85
C19: 45740 | J19: 45741 | P19: =E64 -> 33.71 | T19: =L51 -> 20
A20: 512 | C20: Banque | E20: 8.22 | H20: 512 | J20: Banque | L20: 10.16 | P20: =E80 -> 40 | T20: =L54 -> 20
A21: 666 | C21: Perte de change | E21: 1.78 | H21: 666 | J21: Perte de change | L21: 0.84 | P21: =E87 -> 10 | T21: Total | V21: Total
B22: 41111 | C22: Client - Kellogs | F22: 10 | I22: 41111 | J22: Client - Kellogs | M22: 11 | P22: Total | R22: Total | T22: =SUM(T14:T20) -> 142.39 | V22: =SUM(V14:V15) -> 12.5
C23: 45741 | J23: 45742 | P23: =SUM(P14:P21) -> 235.19 | R23: =SUM(R14:R17) -> 107.23
A24: 419111 | C24: Acompte Client - Kellogs | E24: 30 | H24: 41913 | J24: Acompte Client - JB | L24: 5
B25: 706 | C25: Prestation de service | F25: 30 | I25: 706 | J25: Prestation de service | M25: 5 | Q25: Total | U25: Total
B26: Acompte pour 100 assets Kris Thaesler Paypal | I26: Casino steampunk Acompte | Q26: =P23-R23 -> 127.96 | U26: =T22-V22 -> 129.89
C27: 45741 | J27: 45742
A28: 512 | C28: Banque | E28: 26.8 | H28: 4113 | J28: Client - JB | L28: 25
A29: 666 | C29: Perte de change | E29: =F30-E28 -> 3.2 | I29: 706 | J29: Prestation de service | M29: 25 | R29: CA Total : | S29: =Q26+U26 -> 257.85
B30: 419111 | C30: Acompte Client - Kellogs | F30: 30 | I30: Devis Casino Steampunk Alexandre Coulondre Paypal
C31: 45741 | J31: 45742
A32: 41111 | C32: Client - Kellogs | E32: 150 | H32: 512 | J32: Banque | L32: 5
B33: 706 | C33: Prestation de service | F33: 150 | I33: 41913 | J33: Acompte client - JB | M33: 5
B34: Facture pour 100 assets Kris Thaesler Paypal | J34: 45743
C35: 45743 | H35: 512 | J35: Banque | L35: 67.27 | P35: Dépense team
A36: 512 | C36: Banque | E36: 107.74 | I36: 4552 | J36: Associé - Coraline | M36: 67.27
A37: 666 | C37: Perte de change | E37: =F38-E36 -> 12.26 | I37: Paiement de client Kellogs divisé par 2
B38: 41111 | C38: Client - Kellogs | F38: 120 | J38: 45743
C39: 45743 | H39: 4552 | J39: Associé - Coraline | L39: 2.5
A40: 4551 | C40: Associé - Antoine | E40: 67.27 | I40: 512 | J40: Banque | M40: 2.5
...

Sheet Avril
A1: Liste de client : | D1: Liste d'associé : | F1: Liste de fournisseur :
A2: 4111 | B2: Jack | D2: 4551 | E2: Antoine | F2: 4011 | G2: Soymemox
A3: 4112 | B3: Skye | D3: 4552 | E3: Coraline | F3: 4012 | G3: Axiom
A4: 4113 | B4: JB | D4: 4553 | E4: Roméo | F4: 4016 | G4: Serveur
A5: 4114 | B5: JusteMoi | D5: 4554 | E5: Pastry | R5: Coraline | U5: Antoine | X5: Pastry | Z5: Loper
A6: 4115 | B6: Fulzer | D6: 4555 | E6: Vorloks | R6: 512 | U6: 512 | X6: 512 | Z6: 512
A7: 4116 | B7: Itoka | D7: 4556 | E7: Loper | Q7: D | S7: C | T7: D | V7: C | W7: D | Y7: D
A8: 4117 | B8: Konei | Q8: =F29 -> 20 | S8: =G34 -> 10 | T8: =N25 -> 10 | V8: =O38 -> 4.42 | W8: 131.25 | Y8: 20.26
A9: 4118 | B9: Florian | Q9: =F44 -> 50 | S9: =G49 -> 25 | T9: =N29 -> 25 | V9: =O58 -> 20.26
A10: 4119 | B10: Pourtoutix | Q10: =F56 -> 40 | S10: =G60 -> 20 | T10: =N41 -> 20 | V10: =O74 -> 131.25
A11: 41110 | B11: Scale | Q11: =F70 -> 70 | S11: =G75 -> 35 | T11: =N45 -> 35 | V11: =O82 -> 4.4
A12: 41111 | B12: Kellogs | Q12: =F78 -> 140 | S12: =G83 -> 70 | T12: =N53 -> 22.47 | V12: =O90 -> 10
A13: 41112 | B13: Hichibo | Q13: =F90 -> 10 | S13: =G87 -> 25 | T13: =N61 -> 70 | V13: =O110 -> 6.16
L14: Journal de Antoine | Q14: =F94 -> 42.5 | S14: =G110 -> 45 | T14: =N65 -> 25 | V14: =O119 -> 42.5
L15: Mois d'Avril | Q15: =F105 -> 90 | T15: =N69 -> 100 | V15: =O142 -> 23.8
L16: 45748 | T16: =N85 -> 20 | V16: =O22 -> 6
J17: 2051 | L17: Logiciels | N17: 6 | Q17: TOTAL | S17: TOTAL | T17: TOTAL | V17: TOTAL | W17: TOTAL | Y17: TOTAL
K18: 4016 | L18: Fournisseur - Serveur | O18: 6 | Q18: =SUM(Q8:Q16) -> 462.5 | S18: =SUM(S8:S16) -> 230 | T18: =SUM(T8:T16) -> 327.47 | V18: =SUM(V8:V16) -> 248.79 | W18: =SUM(W8:W16) -> 131.25 | Y18: =SUM(Y8:Y16) -> 20.26
K19: Facture Hebergeur | R19: TOTAL | U19: TOTAL
L20: 45748 | R20: =Q18-S18 -> 232.5 | U20: =T18-V18 -> 78.68
J21: 4016 | L21: Fournisseur - Serveur | N21: 6
D22: Journal de Coraline | K22: 512 | L22: Banque | O22: 6
D23: Mois d'Avril | K23: Paiement 1 mois Hebergeur
D24: 45751 | L24: 45751
B25: 41914 | D25: Acompte Client - JusteMoi | F25: 20 | J25: 512 | L25: Banque | N25: 10
C26: 706 | D26: Prestation de service | G26: 20 | K26: 4552 | L26: Associé - Coraline | O26: 10
C27: Changement de propriétaire | K27: Paiement Acompte Sombrosia divisé par 2
D28: 45751 | L28: 45752
B29: 512 | D29: Banque | F29: 20 | J29: 512 | L29: Banque | N29: 25
C30: 41914 | D30: Acompte Client - JusteMoi | G30: 20 | K30: 4552 | L30: Associé - Coraline | O30: 25
C31: Acompte reçu | K31: Paiement Acompte Kyoka divisé par 2
D32: 45751 | L32: 45758
B33: 4551 | D33: Associé - Antoine | F33: 10 | J33: 706 | L33: Prestation de service | N33: 4.42
C34: 512 | D34: Banque | G34: 10 | K34: 4011 | L34: Fournisseur - Soymemox | O34: 4.42
C35: Paiement Acompte Sombrosia divisé par 2 | K35: Devis Soymemox Guillrmo Armenta Paypal (Render)
D36: 45752 | L36: 45758
B37: 41917 | D37: Acompte Client - Konei | F37: 50 | J37: 4011 | L37: Fournisseur - Soymemox | N37: 4.42
C38: 706 | D38: Prestation de service | G38: 50 | K38: 512 | L38: Banque | O38: 4.42 | Q38: Pourcentage | R38: 0.125 | T38: Dépense team
D39: 45752 | K39: Paiement 2x Render | T39: =O18 -> 6
B40: 4117 | D40: Client - Konei | F40: 150 | L40: 45761 | Q40: Reçu | R40: =150-W8 -> 18.75 | T40: =O34 -> 4.42
...

Sheet Mai
A1: Liste de client : | D1: Liste d'associé : | F1: Liste de fournisseur :
A2: 4111 | B2: Shinlass | D2: 4551 | E2: Antoine | F2: 4011 | G2: Soymemox
A3: 4112 | B3: StaSolaire | D3: 4552 | E3: Coraline | F3: 4012 | G3: Axiom
A4: 4113 | B4: Maxime | D4: 4553 | E4: Roméo | F4: 4013 | G4: Discord
A5: 4114 | B5: AxDev | D5: 4554 | E5: Pastry | F5: 4016 | G5: Serveur
A6: 4115 | B6: FilsOurs | D6: 4555 | E6: Vorloks | K6: Antoine | N6: Coraline | O6: Pastry | P6: Vorloks | Q6: Roméo
A7: 4116 | B7: o700iq | K7: 512 | N7: 512 | O7: 512 | P7: 512 | Q7: 512
A8: 4117 | B8: nuqm | D8: 4557 | E8: Goose | J8: D | L8: C | N8: D | O8: D | P8: D | Q8: D
A9: 4118 | J9: =F38 -> 40 | L9: =G47 -> 78.5 | N9: =G87 -> 70 | O9: =F46 -> 78.5 | P9: =G67 -> 57.37 | Q9: =G51 -> 78.5
A10: 4119 | B10: Pourtoutix | J10: =F42 -> 120 | L10: =G51 -> 78.5 | N10: =G163 -> 40 | Q10: =G190 -> 68
A11: 41110 | B11: Scale | J11: =F62 -> 50 | L11: =G59 -> 4.43
A12: 41111 | J12: =F78 -> 20 | L12: =G67 -> 57.37
A13: 41112 | J13: =F82 -> 140 | L13: =G87 -> 70
J14: =F94 -> 20 | L14: =G103 -> 15.21
J15: =F106 -> 2 | L15: =G123 -> 6.24
J16: =F114 -> 20 | L16: =G155 -> 3.03
J17: =F134 -> 32 | L17: =G163 -> 40
J18: =F146 -> 6 | L18: =G182 -> 23.22
D19: Journal de Antoine | J19: =F158 -> 48 | L19: =G190 -> 68
D20: Mois d'Avril | J20: =F173 -> 32 | L20: =G27 -> 6
D21: 45778 | J21: =F185 -> 58
B22: 2051 | D22: Logiciels | F22: 6
C23: 4016 | D23: Fournisseur - Serveur | G23: 6
C24: Facture Hebergeur
D25: 45778
B26: 4016 | D26: Fournisseur - Serveur | F26: 6
C27: 512 | D27: Banque | G27: 6
C28: Paiement 1 mois Hebergeur
D29: 45779
B30: 41915 | D30: Acompte Client - FilsOurs | F30: 40
C31: 706 | D31: Prestation de service | G31: 40 | J31: TOTAL | L31: TOTAL | N31: TOTAL | O31: TOTAL | P31: TOTAL | Q31: TOTAL
C32: Acompte FilsOurs | J32: =SUM(J9:J29) -> 588 | L32: =SUM(L9:L29) -> 450.5 | N32: =SUM(N9:N29) -> 110 | O32: =SUM(O9:O30) -> 78.5 | P32: =SUM(P9:P29) -> 57.37 | Q32: =SUM(Q9:Q29) -> 146.5
D33: 45779
B34: 4115 | D34: Client - FilsOurs | F34: 100
C35: 706 | D35: Prestation de service | G35: 100 | K35: TOTAL
C36: Devis Naruto Theo Granet Paypal | K36: =J32-L32 -> 137.5
D37: 45779
B38: 512 | D38: Banque | F38: 40
C39: 41915 | D39: Acompte Client - FilsOurs | G39: 40
C40: Acompte reçu
...

Sheet Juin
A1: Liste de client : | D1: Liste d'associé : | G1: Liste de fournisseur :
A2: 4111 | B2: Shinlass | D2: 4551 | E2: Antoine | G2: 4011 | H2: Soymemox
A3: 4112 | B3: Atsuki | D3: 4552 | E3: Coraline | G3: 4012 | H3: Axiom
A4: 4113 | B4: Maxime | D4: 4553 | E4: Roméo | G4: 4013 | H4: Discord
A5: 4114 | B5: Deuxbr | D5: 4554 | E5: Pastry | G5: 4014 | H5: Hybrynix (EzEdit)
A6: 4115 | B6: FilsOurs | D6: 4555 | E6: Vorloks | G6: 4015 | H6: DuoBoosts
A7: 4116 | B7: o700iq | D7: 4556 | E7: Rxverse | G7: 4016 | H7: Serveur
A8: 4117 | B8: nuqm | D8: 4557 | E8: Goose
A9: 4118 | B9: Ved | L9: Antoine | O9: Coraline | P9: Pastry | Q9: Vorloks | R9: Roméo | S9: Rxverse
A10: 4119 | B10: Pourtoutix | L10: 512 | O10: 512 | P10: 512 | Q10: 512 | R10: 512 | S10: 512
A11: 41110 | B11: Muk | K11: D | M11: C | O11: D | P11: D | Q11: D | R11: D | S11: D
A12: 41111 | B12: Skye | K12: =F29 -> 9 | M12: =G34 -> 7.5 | O12: =G34 -> 7.5 | P12: =G150 -> 170 | Q12: =G122 -> 42.5 | R12: =G194 -> 170 | S12: =G74 -> 7
K13: =F45 -> 69.56 | M13: =G74 -> 7 | O13: =G94 -> 90 | S13: =G210 -> 24.29
K14: =F57 -> 160 | M14: =G94 -> 90
K15: =F69 -> 20 | M15: =G122 -> 42.5
K16: =F85 -> 80 | M16: =G142 -> 9.3
K17: =F89 -> 107.96 | M17: =G150 -> 170
D18: Journal de Antoine | K18: =F105 -> 168 | M18: =G190 -> 2.75
D19: Mois de Juin | K19: =F113 -> 40 | M19: =G194 -> 170
D20: 45809 | M20: =G26 -> 6
B21: 2051 | D21: Logiciels | F21: 6
C22: 4016 | D22: Fournisseur - Serveur | G22: 6
C23: Facture Hebergeur
D24: 45809
B25: 4016 | D25: Fournisseur - Serveur | F25: 6
C26: 512 | D26: Banque | G26: 6
C27: Paiement 1 mois Hebergeur
D28: 45810 | K28: =F117 -> 30 | M28: =G202 -> 2.75
B29: 512 | D29: Banque | F29: 9 | K29: =F133 -> 33.06 | M29: =G210 -> 24.29
C30: 4116 | D30: Client - o700iq | G30: 9 | K30: =F145 -> 240 | M30: =G218 -> 22.29
C31: Paiement reçu | K31: =F161 -> 30
D32: 45810 | K32: =F165 -> 20
B33: 4552 | D33: Associé - Coraline | F33: 7.5 | K33: =F173 -> 24
C34: 512 | D34: Banque | G34: 7.5 | K34: =F181 -> 90
C35: Paiement o700iq Divisé par 2 | K35: =F205 -> 32.66
D36: 45810 | K36: TOTAL | M36: TOTAL | O36: TOTAL | P36: TOTAL | Q36: TOTAL | R36: TOTAL | S36: TOTAL
B37: 41912 | D37: Acompte Client - Atsuki | F37: 69.56 | K37: =SUM(K12:K35) -> 1154.24 | M37: =SUM(M12:M35) -> 554.38 | O37: =SUM(O12:O13) -> 97.5 | P37: =SUM(P12:P13) -> 170 | Q37: =SUM(Q12:Q13) -> 42.5 | R37: =SUM(R12:R13) -> 170 | S37: =SUM(S12:S13) -> 31.29
C38: 706 | D38: Prestation de service | G38: 69.56 | L38: TOTAL
C39: Acompte Atsuki Pokemon | L39: =K37-M37 -> 599.86
D40: 45810
...

Sheet Juillet
A1: Liste de client : | D1: Liste d'associé : | G1: Liste de fournisseur :
A2: 4111 | B2: Shinlass | D2: 4551 | E2: Antoine | G2: 4011 | H2: DuoBoosts
A3: 4112 | B3: Atsuki | D3: 4552 | E3: Coraline | G3: 4012 | H3: Axiom
A4: 4113 | B4: Maxime | D4: 4555 | E4: Vorloks | G4: 4013 | H4: Render
A5: 4114 | B5: TryIs | D5: 4556 | E5: Rxverse | G5: 4016 | H5: Serveur
A6: 4115 | B6: FilsOurs | D6: 4554 | E6: Pastry | G6: 4017 | H6: Communication
A7: 4116 | B7: Dina | D7: 4553 | E7: Aleek
A8: 4117 | B8: nuqm | D8: 4557 | E8: Yaagats | M8: Antoine | P8: Coraline | Q8: Aleek | R8: Vorloks | S8: Yaagats | T8: Pastry
A9: 4118 | B9: Ved | M9: 512 | P9: 512 | Q9: 512 | R9: 512 | S9: 512 | T9: 512
A10: 4119 | B10: Pourtoutix | L10: D | N10: C | P10: D | Q10: D | R10: D | S10: D | T10: D
A11: 41110 | B11: Muk | L11: =H44 -> 45 | N11: =I33 -> 11 | P11: =I101 -> 140 | Q11: =I113 -> 148.5 | S11: =I117 -> 168 | T11: =I109 -> 15
A12: 41111 | B12: Skye | L12: =H48 -> 40 | N12: =I69 -> 4.46 | P12: =I125 -> 32.63
L13: =H60 -> 32.51 | N13: =I101 -> 140
L14: =H80 -> 270 | N14: =I109 -> 15
L15: =H84 -> 110 | N15: =I113 -> 148.5
L16: =H96 -> 66.57 | N16: =I117 -> 168
F17: Journal de Antoine | L17: =H104 -> 252 | N17: =I125 -> 32.63
F18: Mois de Juillet | L18: =H120 -> 32.76 | N18: =I133 -> 6.7
F19: 45839 | L19: =H172 -> 46.26 | N19: =I25 -> 6
D20: 2051 | F20: Logiciels | H20: 6 | N20: =I181 -> 5
E21: 4016 | F21: Fournisseur - Serveur | I21: 6 | N21: =I189 -> 40
E22: Facture Hebergeur | N22: =I197 -> 11.8
F23: 45839 | N23: =I205 -> 22.61
D24: 4016 | F24: Fournisseur - Serveur | H24: 6
E25: 512 | F25: Banque | I25: 6
E26: Paiement 1 mois Hebergeur
F27: 45839 | L27: =H144 -> 72 | N27: =I153 -> 5
D28: 606 | F28: Prestation de service | H28: 11 | N28: =I161 -> 10
E29: 4015 | F29: Fournisseur - DuoBoosts | I29: 11
E30: Facture Décoration discord | L30: TOTAL | N30: TOTAL | P30: TOTAL | Q30: TOTAL | R30: TOTAL | S30: TOTAL | T30: TOTAL
F31: 45836 | L31: =SUM(L11:L27) -> 967.1 | N31: =SUM(N11:N29) -> 626.7 | P31: =SUM(P11:P27) -> 172.63 | Q31: =SUM(Q11:Q27) -> 148.5 | R31: =SUM(R11:R27) -> 0 | S31: =SUM(S11:S27) -> 168 | T31: =SUM(T11:T27) -> 15
D32: 4015 | F32: Fournisseur - DuoBoosts | H32: 11 | M32: TOTAL
E33: 512 | F33: Banque | I33: 11 | M33: =L31-N31 -> 340.4
E34: Paiement fait
F35: 45839
D36: 4197 | F36: Acompte Client - Nuqm | H36: 45
E37: 706 | F37: Prestation de service | I37: 45
E38: Acompte Ville 2
F39: 45839
D40: 4117 | F40: Client - Nuqm | H40: =45+47.6 -> 92.6
...

Sheet Août
A1: Liste de client : | D1: Liste d'associé : | G1: Liste de fournisseur :
A2: 4111 | B2: Shinlass | D2: 4551 | E2: Antoine | G2: 4011 | H2: DuoBoosts
A3: 4112 | B3: Hugoxpvp | D3: 4552 | E3: Coraline | G3: 4012 | H3: Axiom
A4: 4113 | B4: Maxime | D4: 4555 | E4: Vorloks | G4: 4013 | H4: Render
A5: 4114 | B5: TryIs | D5: 4556 | E5: Ced | G5: 4016 | H5: Serveur
A6: 4115 | B6: FilsOurs | D6: 4554 | E6: Pastry | G6: 4017 | H6: Communication
A7: 4116 | B7: Dina | D7: 4553 | E7: Aleek
A8: 4117 | B8: nuqm | D8: 4557 | E8: Yaagats
A9: 4118 | B9: Ved | O9: Antoine | R9: Coraline | S9: Aleek | T9: Vorloks | U9: Yaagats | V9: Ced
A10: 4119 | B10: Pourtoutix | O10: 512 | R10: 512 | S10: 512 | T10: 512 | U10: 512 | V10: 512
A11: 41110 | B11: Muk | N11: D | P11: C | R11: D | S11: D | T11: D | U11: D | V11: D
A12: 41111 | B12: Sayame | N12: =H29 -> 108 | P12: =I26 -> 15 | R12: =I38 -> 5 | S12: =I70 -> 49 | T12: =I118 -> 65 | U12: =I34 -> 148.99 | V12: =I94 -> 102
N13: =H49 -> 88 | P13: =I34 -> 148.99 | R13: =I58 -> 340
N14: =H53 -> 410 | P14: =I38 -> 5 | R14: =I66 -> 138
N15: =H61 -> 132 | P15: =I58 -> 340
N16: =H81 -> 280 | P16: =I66 -> 138
N17: =H85 -> 7.8 | P17: =I70 -> 49
F18: Journal de Antoine | N18: =H89 -> 72 | P18: =I94 -> 102
F19: Mois d'août | N19: =H113 -> 50 | P19: =I102 -> 167.67
F20: 45871 | P20: =I110 -> 10.13
D21: 606 | F21: Prestation de service | H21: 15 | P21: =I118 -> 65
E22: 4017 | F22: Fournisseur - Communication | I22: 15 | P22: =I126 -> 22.35
E23: Facture Giveaway | N23: TOTAL | P23: TOTAL
F24: 45871 | N24: =SUM(N12:N22) -> 1147.8 | P24: =SUM(P12:P22) -> 1063.14
D25: 4017 | F25: Fournisseur - Communication | H25: 15
E26: 512 | F26: Banque | I26: 15 | O26: TOTAL | R26: TOTAL | S26: TOTAL | T26: TOTAL | U26: TOTAL | V26: TOTAL
E27: Paiement fait | O27: =N24-P24 -> 84.66 | R27: =SUM(R12:R24) -> 483 | S27: =SUM(S12:S24) -> 49 | T27: =SUM(T12:T24) -> 65 | U27: =SUM(U12:U24) -> 148.99 | V27: =SUM(V12:V24) -> 102
F28: 45875
D29: 512 | F29: Banque | H29: 108
E30: 41110 | F30: Client - Muuk | I30: 108
E31: Paiement reçu
F32: 45875
D33: 4557 | F33: Associé - Yaagats | H33: 148.99
E34: 512 | F34: Banque | I34: 148.99 | M34: Pourcentage | N34: 0.15 | Q34: Dépense team
E35: Paiement Muk | M35: Reçu | N35: =175-I34 -> 26.01 | Q35: =I26 -> 15
F36: 45875 | N36: =220-I66-I70 -> 33 | Q36: =I102 -> 167.67
D37: 4552 | F37: Associé - Coraline | H37: 5 | N37: =120-I94 -> 18 | Q37: =I110 -> 10.13
E38: 512 | F38: Banque | I38: 5 | N38: =74-I118 -> 9 | Q38: =I126 -> 22.35
E39: Paiement Muk
F40: 45875 | M40: TOTAL | N40: =SUM(N35:N39) -> 86.01 | P40: TOTAL | Q40: =SUM(Q35:Q38) -> 215.15
...

Sheet Septembre
A1: Liste de client : | D1: Liste d'associé : | G1: Liste de fournisseur :
A2: 4111 | B2: Dawn | D2: 4551 | E2: Antoine | G2: 4011 | H2: DuoBoosts
A3: 4112 | B3: MagikViruz | D3: 4552 | E3: Coraline | G3: 4012 | H3: Axiom
A4: 4113 | B4: Hesty | D4: 4555 | E4: Jidnesh | G4: 4013 | H4: Render
A5: 4114 | B5: TryIs | D5: 4556 | E5: Ced | G5: 4016 | H5: Serveur | N5: Antoine | Q5: Archibald | R5: Ced | S5: Jidnesh
A6: 4115 | B6: Alkazia | D6: 4554 | E6: Archibald | G6: 4017 | H6: Communication | N6: 512 | Q6: 512 | R6: 512 | S6: 512
A7: 4116 | B7: Dina | D7: 4553 | E7: Aleek | G7: 4018 | H7: Autre | M7: D | O7: C | Q7: D | R7: D | S7: D
A8: 4117 | B8: nuqm | D8: 4557 | E8: Yaagats | M8: =H38 -> 23.92 | O8: =I27 -> 8.92 | Q8: =I135 -> 42.5 | R8: =I123 -> 42.5 | S8: =I115 -> 36
A9: 4118 | B9: Ved | M9: =H50 -> 520 | O9: =I59 -> 8
A10: 4119 | B10: Pourtoutix | M10: =H86 -> 18 | O10: =I67 -> 10.2
A11: 41110 | B11: Muk | M11: =H98 -> 27 | O11: =I75 -> 38.34
A12: 41111 | B12: Sayame | M12: =H110 -> 400 | O12: =I95 -> 12.74
M13: =H118 -> 23.92 | O13: =I115 -> 36
M14: =H130 -> 50 | O14: =I123 -> 42.5
O15: =I135 -> 42.5
O16: =I143 -> 22.25
M18: TOTAL | O18: TOTAL | Q18: TOTAL | R18: TOTAL | S18: TOTAL
F19: Journal de Antoine | M19: =SUM(M8:M16) -> 1062.84 | O19: =SUM(O8:O16) -> 221.45 | Q19: =Q8 -> 42.5 | R19: =R8 -> 42.5 | S19: =S8 -> 36
F20: Mois de septembre
F21: 45902 | N21: TOTAL
D22: 606 | F22: Prestation de service | H22: 8.92 | N22: =M19-O19 -> 841.39
E23: 4017 | F23: Fournisseur - Communication | I23: 8.92
E24: Brabus Communication
F25: 45902
D26: 4017 | F26: Fournisseur - Communication | H26: 8.92 | L26: Pourcentage | M26: 0.15 | O26: Dépense team
E27: 512 | F27: Banque | I27: 8.92 | L27: Reçu | M27: =I83-I115 -> 9 | O27: =I27 -> 8.92
E28: Paiement fait | M28: =I35-I123 -> 5.34 | O28: =I59 -> 8
F29: 45907 | M29: =I131-I135 -> 7.5 | O29: =I67 -> 10.2
D30: 4191 | F30: Acompte Client - Dawn | H30: 23.92 | O30: =I75 -> 38.34
E31: 706 | F31: Prestation de service | I31: 23.92 | L31: TOTAL | M31: =SUM(M27:M29) -> 21.84 | O31: =I95 -> 12.74
E32: Acompte Donjon | O32: =I143 -> 22.25
F33: 45907
D34: 4111 | F34: Client - Dawn | H34: 47.84 | O34: TOTAL
E35: 706 | F35: Prestation de service | I35: 47.84 | O35: =SUM(O27:O32) -> 100.45
E36: Devis Donjon
F37: 45907
D38: 512 | F38: Banque | H38: 23.92
E39: 4191 | F39: Acompte Client - Dawn | I39: 23.92
E40: Acompte reçu
F41: 45909
...

Sheet Octobre
A1: Liste de client : | D1: Liste d'associé : | G1: Liste de fournisseur :
A2: 4111 | B2: Dawn | D2: 4551 | E2: Antoine | G2: 4011 | H2: DuoBoosts
A3: 4112 | B3: MagikViruz | D3: 4552 | E3: Coraline | G3: 4012 | H3: Axiom
A4: 4113 | B4: Hesty | D4: 4555 | E4: Jidnesh | G4: 4013 | H4: Render | M4: Antoine | P4: Coraline | Q4: Mathis | R4: Jidnesh | S4: Ced
A5: 4114 | B5: TryIs | D5: 4556 | E5: Ced | G5: 4016 | H5: Serveur | M5: 512 | P5: 512 | Q5: 512 | R5: 512 | S5: 512
A6: 4115 | B6: Kamdin | D6: 4554 | E6: Archibald | G6: 4017 | H6: Communication | L6: D | N6: C | P6: D | Q6: D | R6: D | S6: D
A7: 4116 | B7: DeuxBr | D7: 4553 | E7: Mathis | G7: 4018 | H7: Autre | L7: =G26 -> 30 | N7: =H31 -> 27.6 | P7: =H31 -> 27.6 | Q7: =H75 -> 240 | R7: =H139 -> 425 | S7: =H143 -> 425
A8: 4117 | B8: Aly | D8: 4557 | E8: Yaagats | L8: =G42 -> 25 | N8: =H59 -> 6
A9: 4118 | B9: Zosco | L9: =G50 -> 25 | N9: =H75 -> 240
A10: 4119 | B10: Pourtoutix | L10: =G70 -> 480 | N10: =H139 -> 425
A11: 41110 | B11: Shawzer | L11: =G86 -> 100 | N11: =H143 -> 425
A12: 41111 | B12: Sayame | L12: =G90 -> 15 | N12: =H151 -> 25.8
L13: =G102 -> 32 | N13: =H183 -> 22.25
L14: =G114 -> 85
L15: =G122 -> 140
L16: =G126 -> 600
L17: =G134 -> 200
L18: =G162 -> 32.5
E19: Journal de Antoine | L19: =G174 -> 98.72
E20: Mois d'octobre
E21: 45935
C22: 4116 | E22: Client - DeuxBr | G22: 30
D23: 706 | E23: Prestation de service | H23: 30 | L23: TOTAL | N23: TOTAL | P23: TOTAL | Q23: TOTAL | R23: TOTAL | S23: TOTAL
D24: Devis Modification spawn | L24: =SUM(L7:L22) -> 1863.22 | N24: =SUM(N7:N22) -> 1171.65 | P24: =P7 -> 27.6 | Q24: =Q7 -> 240 | R24: =R7 -> 425 | S24: =S7 -> 425
E25: 45935
C26: 512 | E26: Banque | G26: 30 | M26: TOTAL
D27: 4116 | E27: Client - DeuxBr | H27: 30 | M27: =L24-N24 -> 691.57
D28: Paiement reçu
E29: 45935
C30: 4552 | E30: Associé - Coraline | G30: 27.6
D31: 512 | E31: Banque | H31: 27.6
D32: Paiement Map Deuxbr
E33: 45936 | K33: Pourcentage | L33: 0.15 | N33: Dépense team
C34: 4196 | E34: Acompte Client - Deuxbr | G34: 25 | K34: Reçu | L34: =30-H31 -> 2.4 | N34: =H59 -> 6
D35: 706 | E35: Prestation de service | H35: 25 | L35: =1000-H139-H143 -> 150 | N35: =H151 -> 25.8
D36: Acompte | N36: =H183 -> 22.25
E37: 45936 | K37: TOTAL | L37: =SUM(L34:L36) -> 152.4 | N37: TOTAL
C38: 4116 | E38: Client - DeuxBr | G38: 50 | N38: =SUM(N34:N36) -> 54.05
D39: 706 | E39: Prestation de service | H39: 50
D40: Devis Modif Sombrosia
...

Sheet Total
A1: Antoine | B1: Coraline | C1: Ced | D1: Spinophore | E1: Archibald | F1: Dalphou | G1: Hqky | H1: Yumitsuki | I1: Mathis | J1: Jidnesh | K1: Vorloks | L1: Aleek | M1: Loper | N1: Rxverse | O1: Roméo | P1: Pastry | Q1: Yaagats | R1: Team | S1: Pourcentage | T1: Dépense team
A2: =Mars!U26+Avril!U20+Mai!K36+Juin!L39+Juillet!M33+'Août'!O27+Septembre!N22+Octobre!M27 -> 2903.95 | B2: =Mars!Q26+Avril!R20+Mai!N32+Juin!O37+Juillet!P31+'Août'!R27+Octobre!P24 -> 1251.19 | C2: ='Août'!V27+Septembre!R19+Octobre!S24 -> 569.5 | E2: =Septembre!Q19 -> 42.5 | I2: =Octobre!Q24 -> 240 | J2: =Septembre!S19+Octobre!R24 -> 461 | K2: =65.63+Mai!P32+Juin!Q37+Juillet!R31+'Août'!T27 -> 230.5 | L2: =Juillet!Q31+'Août'!S27 -> 197.5 | M2: =Avril!Y8 -> 20.26 | N2: =Juin!S37 -> 31.29 | O2: =Mai!Q32+Juin!R37 -> 316.5 | P2: =Avril!W18+Mai!O32+Juin!P37+Juillet!T31-65.63 -> 329.12 | Q2: =Juillet!S31+'Août'!U27 -> 316.99 | R2: =SUM(A2:Q2) -> 6910.3 | S2: =Avril!R43+Mai!J53+Juin!K48+Juillet!M48+'Août'!N40+Septembre!M31+Octobre!L37 -> 467.13 | T2: =Avril!T45+Mai!L54+Juin!M49+Juillet!O53+'Août'!Q40+Septembre!O35+Octobre!N38 -> 627.22
